Workbook

Sheet README
A1: Chow Tai Seng – Sydney Single Store P&L Model (v6)
A3: How to use (quick):
A4: 1) Go to 'P&L_Annual' and select a Location_ID in cell B3 (drop-down).
A5: 2) Update global assumptions in 'Inputs_Global' (BLUE inputs). Yellow values are UNCONFIRMED and need sources/quotes.
A6: 3) 'Locations' calculates Sales_Index from income + footfall proxies (indices and weights).
A7: 4) P&L_Annual uses: Revenue = Store_Size × Sales_per_sqm × Sales_Index; costs follow Inputs_Global assumptions.
A8: 5) 'LocationOutputs' compares all candidate locations and now includes Initial_Investment_AUD per location.
A9: 6) NPV table is at the bottom of 'P&L_Annual' (5y horizon; discount = CPI; sales growth = 5%; costs escalate with CPI).
A11: Why Sales_Index exists (and how it’s calculated):
A12: ! We don’t have store-level revenue/footfall for each candidate street/mall. Instead, we keep revenue driver-based and make it district-sensitive using proxies:
A13: Revenue (annual) = Store_Size_sqm × Base_Sales_per_sqm × Sales_Index
A14: Sales_Index = w_income × Income_Index + w_footfall × Footfall_Index
... A28: If Excel shows any warnings, they should not be formula errors (#NAME, #REF, etc.). There should be none in this file.

Sheet Inputs_Global
A1: Global assumptions (edit BLUE cells) | D1: Yellow cells means that infromation still need to be proved by reliable sources OR checked by the whole group
A3: Assumption | B3: Value | C3: Units | D3: Rationale (why we use it) | E3: Source_URL(s)
A4: Default store size | B4: 60 | C4: sqm | D4: Starting point based on typical specialty jewellery unit size in malls; overwrite per location if known. UNCONFIRMED: validate with market benchmarks/quotes. | E4: General assumption form Martin's Data
A5: Sales per sqm (base) | B5: 27500 | C5: AUD / sqm / year | D5: Base sales density for Year‑1 before Sales_Index. Pulled from Scentre Group 2024 Property Compendium: Westfield Sydney specialty sales (MAT) for specialty stores <400sqm is ~A$27.5k per sqm (2024). Use as defensible starting point until CTS store benchmarks are available. | E5: https://assets.ctfassets.net/0vreywxqlgab/2jCDgyNRHOqTByrcni3uKv/47f440c291228ef086d42355f46d237f/2024_Property_Compendium.xlsx UNCONFIRMED – replace with CTS benchmark if available
A6: Sales_Index (default) | B6: 1 | C6: x | D6: Location multiplier applied to base sales per sqm. Each location has its own Sales_Index input. UNCONFIRMED: validate with market benchmarks/quotes. | E6: Default value
A7: Gross margin | B7: 0.6 | C7: % of sales | D7: Gross margin % of sales (blended). Jewellery retailers in Australia/NZ report ~60% gross margin (e.g., Michael Hill reported ~60.4% in FY2024). Use as starting point until CTS product mix and target margin are provided. | E7: https://announcements.asx.com.au/asxpdf/20240829/pdf/0668rfd20kzj4j.pdf UNCONFIRMED – refine with CTS mix/target margin
A8: Merchant fee rate | B8: 0.009 | C8: % of sales | D8: Card payment fees as % of sales (blended). | E8: https://www.rba.gov.au/statistics/frequency/retail-payments/2025/retail-payments-0225.html
A9: Marketing – fixed | B9: 20000 | C9: AUD / first initial year | D9: Fixed local activation / PR / community events budget for a new store (baseline). Kept separate from %‑of‑sales variable spend because a new market entry often has minimum run‑rate activity even at low sales. Treat as placeholder until CTS launch plan/agency quotes are available. | E9: https://www.etropo.com/blog/marketing-budgeting/average-marketing-budget-by-industry UNCONFIRMED – needs CTS launch plan/quotes
A10: Marketing – variable | B10: 0.05 | C10: % of sales | D10: Variable marketing spend as % of sales (ongoing campaigns, promo, influencer/affiliate, performance). Benchmark ranges for retail marketing budgets are commonly cited around ~5–9% of revenue; we set 4% as a conservative lower-bound and keep a separate fixed local-activation budget. Adjust once CTS go‑to‑market plan is confirmed. | E10: https://www.etropo.com/blog/marketing-budgeting/average-marketing-budget-by-industry https://www.gartner.com/en/articles/gartner-cmo-spend-survey-2024
A11: Logistics & import (excl. GST) | B11: 40000 | C11: AUD / year | D11: Placeholder for international freight + customs brokerage + import processing charges + local handling/warehousing for imported inventory. Order‑of‑magnitude check: freight+brokerage often lands in low single‑digit % of import value; for a store with high inventory throughput this can translate to ~A$10–50k/yr. Replace with logistics quotes and actual duty/IPC. | E11: UNCONFIRMED – needs freight/broker quotes
A12: Admin & compliance | B12: 20000 | C12: AUD / year | D12: Bundle for accounting/bookkeeping, company compliance (ASIC), software (accounting/POS), bank fees, basic legal/admin. Use as placeholder until CTS ops stack and outsourcing decisions are known (in‑house vs outsourced bookkeeping). | E12: UNCONFIRMED – refine with CTS toolstack & accountant quote
A13: Utilities | B13: 150 | C13: AUD / sqm / year | D13: Electricity + utilities proxy for a small retail unit. Many mall leases also recover some utilities via outgoings, so treat as placeholder until lease terms are confirmed. Scaled to ~A$9k/yr for 60sqm (150/sqm/yr). | E13: UNCONFIRMED – validate with lease + retailer bills
A14: Insurance | B14: 6000 | C14: AUD / year | D14: Business insurance proxy (public liability + property/contents; jewellery stock cover may materially increase premium). Use as placeholder until broker quote using CTS inventory value and security measures is obtained. | E14: UNCONFIRMED – needs broker quote incl. stock cover
A15: Fitout capex | B15: 2500 | C15: AUD / sqm | D15: Fitout benchmark for retail boutiques (range-based); replace with Sydney contractor quotes. Used for initial investment and depreciation. | E15: https://www.totalfitouts.com.au/blog/2025-pricing-per-square-meter-m%C2%B2-for-fitouts-in-australia/
... A32: Cost escalation (annual, CPI) | B32: 0.038 | C32: % | D32: Assume rent and fixed OPEX escalate with CPI (nominal). | E32: https://www.abs.gov.au/media-centre/media-releases/cpi-rose-38-year-december-2025

Sheet Locations
A1: Locations (edit BLUE cells; proxies & indices drive Sales_Index)
A3: Location_ID | B3: Area | C3: Anchor Location | D3: Location_Type | E3: Store_Size_sqm | F3: Rent_Total_AUD_pa | G3: Rent_per_sqm_pa | H3: Sales_Index | I3: Notes | J3: Forecast_Net_Income_AUD_pa | K3: Income_Proxy_HH_Weekly | L3: Income_Source_URL | M3: Footfall_Proxy | N3: Footfall_Source_URL | O3: Income_Index | P3: Footfall_Index
A4: WF_SYD_PRIME | B4: Sydney | C4: Westfield Sydney | D4: Westfield | E4: 60 | F4: 485000 | G4: =IFERROR(F4/E4,"") -> 8083.3333 | H4: =Inputs_Global!$B$22*O4+Inputs_Global!$B$23*P4 -> 1.0361098 | I4: Highest footfall, highest risk | J4: =IFERROR(VLOOKUP(A4,LocationOutputs!$A$4:$K$200,11,FALSE),"") -> -26716.61 | K4: 2227 | L4: https://abs.gov.au/census/find-census-data/quickstats/2021/SAL13730 | M4: 33.459555 | N4: https://assets.ctfassets.net/0vreywxqlgab/2jCDgyNRHOqTByrcni3uKv/47f440c291228ef086d42355f46d237f/2024_Property_Compendium.xlsx | O4: =IFERROR(K4/Inputs_Global!$B$24,1) -> 1.0722195 | P4: =IFERROR(M4/Inputs_Global!$B$25,1) -> 1
A5: WF_SYD_SECOND | B5: Sydney | C5: Westfield Sydney | D5: Westfield | E5: 60 | F5: 350000 | G5: =IFERROR(F5/E5,"") -> 5833.3333 | H5: =Inputs_Global!$B$22*O5+Inputs_Global!$B$23*P5 -> 1.0361098 | I5: Lower visibility but still premium | J5: =IFERROR(VLOOKUP(A5,LocationOutputs!$A$4:$K$200,11,FALSE),"") -> 81212.542 | K5: 2227 | L5: https://abs.gov.au/census/find-census-data/quickstats/2021/SAL13730 | M5: 33.459555 | N5: https://assets.ctfassets.net/0vreywxqlgab/2jCDgyNRHOqTByrcni3uKv/47f440c291228ef086d42355f46d237f/2024_Property_Compendium.xlsx | O5: =IFERROR(K5/Inputs_Global!$B$24,1) -> 1.0722195 | P5: =IFERROR(M5/Inputs_Global!$B$25,1) -> 1
A6: WF_BONDI | B6: Bondi Junction | C6: Westfield Bondi Junction | D6: Westfield | E6: 60 | F6: 287500 | G6: =IFERROR(F6/E6,"") -> 4791.6667 | H6: =Inputs_Global!$B$22*O6+Inputs_Global!$B$23*P6 -> 0.87455521 | I6: Tourist + affluent locals | J6: =IFERROR(VLOOKUP(A6,LocationOutputs!$A$4:$K$200,11,FALSE),"") -> 19928.784 | K6: 2566 | L6: https://abs.gov.au/census/find-census-data/quickstats/2021/118011341 | M6: 17.187327 | N6: https://assets.ctfassets.net/0vreywxqlgab/2jCDgyNRHOqTByrcni3uKv/47f440c291228ef086d42355f46d237f/2024_Property_Compendium.xlsx | O6: =IFERROR(K6/Inputs_Global!$B$24,1) -> 1.2354357 | P6: =IFERROR(M6/Inputs_Global!$B$25,1) -> 0.5136747
A7: WF_PARRA | B7: Parramatta | C7: Westfield Parramatta | D7: Westfield | E7: 60 | F7: 250000 | G7: =IFERROR(F7/E7,"") -> 4166.6667 | H7: =Inputs_Global!$B$22*O7+Inputs_Global!$B$23*P7 -> 0.97384697 | I7: Strong conversion, lower rent pressure | J7: =IFERROR(VLOOKUP(A7,LocationOutputs!$A$4:$K$200,11,FALSE),"") -> 114528.37 | K7: 2092 | L7: https://abs.gov.au/census/find-census-data/quickstats/2021/SAL13167 | M7: 31.467774 | N7: https://assets.ctfassets.net/0vreywxqlgab/2jCDgyNRHOqTByrcni3uKv/47f440c291228ef086d42355f46d237f/2024_Property_Compendium.xlsx | O7: =IFERROR(K7/Inputs_Global!$B$24,1) -> 1.007222 | P7: =IFERROR(M7/Inputs_Global!$B$25,1) -> 0.94047198
A8: WF_CHATSWOOD | B8: Chatswood | C8: Westfield Chatswood | D8: Westfield | E8: 60 | F8: 260000 | G8: =IFERROR(F8/E8,"") -> 4333.3333 | H8: =Inputs_Global!$B$22*O8+Inputs_Global!$B$23*P8 -> 0.76115822 | I8: High Asian consumer density | J8: =IFERROR(VLOOKUP(A8,LocationOutputs!$A$4:$K$200,11,FALSE),"") -> -47152.114 | K8: 2123 | L8: https://abs.gov.au/census/find-census-data/quickstats/2021/121011684 | M8: 16.735436 | N8: https://assets.ctfassets.net/0vreywxqlgab/2jCDgyNRHOqTByrcni3uKv/47f440c291228ef086d42355f46d237f/2024_Property_Compendium.xlsx | O8: =IFERROR(K8/Inputs_Global!$B$24,1) -> 1.0221473 | P8: =IFERROR(M8/Inputs_Global!$B$25,1) -> 0.50016911
A9: WF_MIRANDA | B9: Miranda | C9: Westfield Miranda | D9: Westfield | E9: 60 | F9: 210000 | G9: =IFERROR(F9/E9,"") -> 3500 | H9: =Inputs_Global!$B$22*O9+Inputs_Global!$B$23*P9 -> 0.68610411 | I9: Family-driven spending | J9: =IFERROR(VLOOKUP(A9,LocationOutputs!$A$4:$K$200,11,FALSE),"") -> -64149.169 | K9: 1920 | L9: https://abs.gov.au/census/find-census-data/quickstats/2021/SAL12656 | M9: 14.983122 | N9: https://assets.ctfassets.net/0vreywxqlgab/2jCDgyNRHOqTByrcni3uKv/47f440c291228ef086d42355f46d237f/2024_Property_Compendium.xlsx | O9: =IFERROR(K9/Inputs_Global!$B$24,1) -> 0.92441021 | P9: =IFERROR(M9/Inputs_Global!$B$25,1) -> 0.44779801
A10: WF_WARRINGAH | B10: Warringah Mall | C10: Westfield Warringah Mall | D10: Westfield | E10: 60 | F10: 250000 | G10: =IFERROR(F10/E10,"") -> 4166.6667 | H10: =Inputs_Global!$B$22*O10+Inputs_Global!$B$23*P10 -> 0.67380065 | I10: Lifestyle-focused centre | J10: =IFERROR(VLOOKUP(A10,LocationOutputs!$A$4:$K$200,11,FALSE),"") -> -115131.85 | K10: 2127 | L10: https://abs.gov.au/census/find-census-data/quickstats/2021/SAL10598 | M10: 10.825107 | N10: https://assets.ctfassets.net/0vreywxqlgab/2jCDgyNRHOqTByrcni3uKv/47f440c291228ef086d42355f46d237f/2024_Property_Compendium.xlsx | O10: =IFERROR(K10/Inputs_Global!$B$24,1) -> 1.0240732 | P10: =IFERROR(M10/Inputs_Global!$B$25,1) -> 0.32352812
A11: ST_CBD_CASTL | B11: Sydney CBD | C11: Castlereagh St luxury cluster | D11: Street High-End | E11: 60 | F11: 450000 | G11: =IFERROR(F11/E11,"") -> 7500 | H11: =Inputs_Global!$B$22*O11+Inputs_Global!$B$23*P11 -> 1.0074627 | I11: Assumed street rent; replace with lease comps. | J11: =IFERROR(VLOOKUP(A11,LocationOutputs!$A$4:$K$200,11,FALSE),"") -> -17288.433 | K11: 2108 | L11: https://abs.gov.au/census/find-census-data/quickstats/2021/117031646 | M11: 33.459555 | N11: https://assets.ctfassets.net/0vreywxqlgab/2jCDgyNRHOqTByrcni3uKv/47f440c291228ef086d42355f46d237f/2024_Property_Compendium.xlsx | O11: =IFERROR(K11/Inputs_Global!$B$24,1) -> 1.0149254 | P11: =IFERROR(M11/Inputs_Global!$B$25,1) -> 1
A12: ST_CBD_PITT | B12: Sydney CBD | C12: Pitt St Mall jewellery cluster | D12: Street Prime Strip | E12: 60 | F12: 780000 | G12: =IFERROR(F12/E12,"") -> 13000 | H12: =Inputs_Global!$B$22*O12+Inputs_Global!$B$23*P12 -> 1.0074627 | I12: Prime strip rent anchored to public reports; validate feasibility. | J12: =IFERROR(VLOOKUP(A12,LocationOutputs!$A$4:$K$200,11,FALSE),"") -> -347288.43 | K12: 2108 | L12: https://abs.gov.au/census/find-census-data/quickstats/2021/117031646 | M12: 33.459555 | N12: https://assets.ctfassets.net/0vreywxqlgab/2jCDgyNRHOqTByrcni3uKv/47f440c291228ef086d42355f46d237f/2024_Property_Compendium.xlsx | O12: =IFERROR(K12/Inputs_Global!$B$24,1) -> 1.0149254 | P12: =IFERROR(M12/Inputs_Global!$B$25,1) -> 1
A13: ST_CHIN_HAY | B13: Chinatown | C13: Hay St Chinese jewellery strip | D13: Street Ethnic Cluster | E13: 60 | F13: 180000 | G13: =IFERROR(F13/E13,"") -> 3000 | H13: =Inputs_Global!$B$22*O13+Inputs_Global!$B$23*P13 -> 0.96485315 | I13: Assumed street rent; replace with market evidence. | J13: =IFERROR(VLOOKUP(A13,LocationOutputs!$A$4:$K$200,11,FALSE),"") -> 161007.13 | K13: 1931 | L13: https://abs.gov.au/census/find-census-data/quickstats/2021/SAL11884 | M13: 33.459555 | N13: https://assets.ctfassets.net/0vreywxqlgab/2jCDgyNRHOqTByrcni3uKv/47f440c291228ef086d42355f46d237f/2024_Property_Compendium.xlsx | O13: =IFERROR(K13/Inputs_Global!$B$24,1) -> 0.92970631 | P13: =IFERROR(M13/Inputs_Global!$B$25,1) -> 1
A14: ST_CHAT_VIC | B14: Chatswood | C14: Victoria Ave retail strip | D14: Street High Street | E14: 60 | F14: 270000 | G14: =IFERROR(F14/E14,"") -> 4500 | H14: =Inputs_Global!$B$22*O14+Inputs_Global!$B$23*P14 -> 0.76115822 | I14: Assumed street rent; replace with lease comps. | J14: =IFERROR(VLOOKUP(A14,LocationOutputs!$A$4:$K$200,11,FALSE),"") -> -57152.114 | K14: 2123 | L14: https://abs.gov.au/census/find-census-data/quickstats/2021/121011684 | M14: 16.735436 | N14: https://assets.ctfassets.net/0vreywxqlgab/2jCDgyNRHOqTByrcni3uKv/47f440c291228ef086d42355f46d237f/2024_Property_Compendium.xlsx | O14: =IFERROR(K14/Inputs_Global!$B$24,1) -> 1.0221473 | P14: =IFERROR(M14/Inputs_Global!$B$25,1) -> 0.50016911

Sheet P&L_Annual
A1: Single Store Profit & Loss (Annual view)
A3: Selected Location_ID | B3: WF_PARRA
A5: Location summary (auto)
A6: Area | B6: =IFERROR(VLOOKUP($B$3,Locations!$A$4:$J$200,2,FALSE),"") -> Parramatta
A7: Anchor | B7: =IFERROR(VLOOKUP($B$3,Locations!$A$4:$J$200,3,FALSE),"") -> Westfield Parramatta
A8: Type | B8: =IFERROR(VLOOKUP($B$3,Locations!$A$4:$J$200,4,FALSE),"") -> Westfield
A9: Store size (sqm) | B9: =IFERROR(VLOOKUP($B$3,Locations!$A$4:$J$200,5,FALSE),"") -> 60
A10: Rent total (pa) | B10: =IFERROR(VLOOKUP($B$3,Locations!$A$4:$J$200,6,FALSE),"") -> 250000
A11: Sales_Index | B11: =IFERROR(VLOOKUP($B$3,Locations!$A$4:$J$200,8,FALSE),"") -> 0.97384697
A14: P&L (Year 1)
A15: Line item | B15: AUD / year
A16: Revenue | B16: =B9*Inputs_Global!$B$5*B11 -> 1606847.5
A17: COGS | B17: =-B16*(1-Inputs_Global!$B$7) -> -642739
A18: Gross Profit | B18: =B16+B17 -> 964108.5
A20: Rent (total) | B20: =-B10 -> -250000
A21: Labour (wages) | B21: =-(Inputs_Global!$B$17 + Inputs_Global!$B$18*Inputs_Global!$B$19) -> -305000
A22: Superannuation | B22: =B21*Inputs_Global!$B$20 -> -36600
A23: Merchant fees | B23: =-B16*Inputs_Global!$B$8 -> -14461.627
A24: Marketing (fixed + variable) | B24: =-(Inputs_Global!$B$9 + B16*Inputs_Global!$B$10) -> -100342.37
A25: Logistics & import | B25: =-Inputs_Global!$B$11 -> -40000
A26: Utilities | B26: =-(Inputs_Global!$B$13*B9) -> -9000
A27: Insurance | B27: =-Inputs_Global!$B$14 -> -6000
A28: Admin & compliance | B28: =-Inputs_Global!$B$12 -> -20000
A29: Depreciation (fitout) | B29: =-(Inputs_Global!$B$15*B9/Inputs_Global!$B$16) -> -30000
A30: Total OPEX | B30: =SUM(B20:B29) -> -811404
A31: EBIT | B31: =B18+B30 -> 152704.5
A32: Income tax | B32: =-MAX(0,B31)*Inputs_Global!$B$21 -> -38176.124
A33: Net Income | B33: =B31+B32 -> 114528.37
A36: NPV analysis (5-year horizon)
A37: Assumptions: 5y horizon; discount rate = AU CPI (annual); sales growth = 5% p.a.; costs escalate with CPI.
A38: Discount rate source (ABS CPI Dec-2025): | B38: https://www.abs.gov.au/media-centre/media-releases/cpi-rose-38-year-december-2025
A40: Item | B40: Y0 | C40: Y1 | D40: Y2 | E40: Y3 | F40: Y4 | G40: Y5
A41: Initial investment (cash outflow) | B41: =-(Inputs_Global!$B$15*$B$9 + (-$B$17)*Inputs_Global!$B$28/12 + $B$10*Inputs_Global!$B$27/12 + Inputs_Global!$B$29) -> -393184.75
A42: Revenue | C42: =$B$16 -> 1606847.5 | D42: =$B$16*(1+Inputs_Global!$B$31)^1 -> 1687189.9 | E42: =$B$16*(1+Inputs_Global!$B$31)^2 -> 1771549.4 | F42: =$B$16*(1+Inputs_Global!$B$31)^3 -> 1860126.8 | G42: =$B$16*(1+Inputs_Global!$B$31)^4 -> 1953133.2
A43: EBIT | C43: =$B$31 -> 152704.5 | D43: =D42 + (-D42*(1-Inputs_Global!$B$7)) + (-D42*Inputs_Global!$B$8) + (-D42*Inputs_Global!$B$10) + (-(Inputs_Global!$B$9)*(1+Inputs_Global!$B$32)^1) + (($B$20+$B$21+$B$22+$B$25+$B$26+$B$27+$B$28)*(1+Inputs_Global!$B$32)^1) + $B$29 -> 170078.92 | E43: =E42 + (-E42*(1-Inputs_Global!$B$7)) + (-E42*Inputs_Global!$B$8) + (-E42*Inputs_Global!$B$10) + (-(Inputs_Global!$B$9)*(1+Inputs_Global!$B$32)^2) + (($B$20+$B$21+$B$22+$B$25+$B$26+$B$27+$B$28)*(1+Inputs_Global!$B$32)^2) + $B$29 -> 188635.16 | F43: =F42 + (-F42*(1-Inputs_Global!$B$7)) + (-F42*Inputs_Global!$B$8) + (-F42*Inputs_Global!$B$10) + (-(Inputs_Global!$B$9)*(1+Inputs_Global!$B$32)^3) + (($B$20+$B$21+$B$22+$B$25+$B$26+$B$27+$B$28)*(1+Inputs_Global!$B$32)^3) + $B$29 -> 208444.19 | G43: =G42 + (-G42*(1-Inputs_Global!$B$7)) + (-G42*Inputs_Global!$B$8) + (-G42*Inputs_Global!$B$10) + (-(Inputs_Global!$B$9)*(1+Inputs_Global!$B$32)^4) + (($B$20+$B$21+$B$22+$B$25+$B$26+$B$27+$B$28)*(1+Inputs_Global!$B$32)^4) + $B$29 -> 229581.01
A44: Income tax | C44: =$B$32 -> -38176.124 | D44: =-MAX(0,D43)*Inputs_Global!$B$21 -> -42519.73 | E44: =-MAX(0,E43)*Inputs_Global!$B$21 -> -47158.789 | F44: =-MAX(0,F43)*Inputs_Global!$B$21 -> -52111.048 | G44: =-MAX(0,G43)*Inputs_Global!$B$21 -> -57395.253
A45: Net income | C45: =$B$33 -> 114528.37 | D45: =D43+D44 -> 127559.19 | E45: =E43+E44 -> 141476.37 | F45: =F43+F44 -> 156333.14 | G45: =G43+G44 -> 172185.76
A46: Add back depreciation | C46: =-$B$29 -> 30000 | D46: =-$B$29 -> 30000 | E46: =-$B$29 -> 30000 | F46: =-$B$29 -> 30000 | G46: =-$B$29 -> 30000
A47: Free cash flow | B47: =B41 -> -393184.75 | C47: =C45+C46 -> 144528.37 | D47: =D45+D46 -> 157559.19 | E47: =E45+E46 -> 171476.37 | F47: =F45+F46 -> 186333.14 | G47: =G45+G46 -> 202185.76
A48: Discount factor | B48: =1 -> 1 | C48: =1/(1+Inputs_Global!$B$30)^1 -> 0.96339114 | D48: =1/(1+Inputs_Global!$B$30)^2 -> 0.92812248 | E48: =1/(1+Inputs_Global!$B$30)^3 -> 0.89414497 | F48: =1/(1+Inputs_Global!$B$30)^4 -> 0.86141134 | G48: =1/(1+Inputs_Global!$B$30)^5 -> 0.82987605
...

Sheet LocationOutputs
A1: Location comparison (computed from same drivers as P&L)
A3: Location_ID | B3: Area | C3: Type | D3: Store_Size_sqm | E3: Rent_Total_pa | F3: Sales_Index | G3: Revenue_pa | H3: Gross_Profit_pa | I3: Total_OPEX_pa | J3: EBIT_pa | K3: Net_Income_pa | L3: Initial_Investment_AUD
A4: WF_SYD_PRIME | B4: =IFERROR(VLOOKUP($A4,Locations!$A$4:$J$200,2,FALSE),"") -> Sydney | C4: =IFERROR(VLOOKUP($A4,Locations!$A$4:$J$200,4,FALSE),"") -> Westfield | D4: =IFERROR(VLOOKUP($A4,Locations!$A$4:$J$200,5,FALSE),"") -> 60 | E4: =IFERROR(VLOOKUP($A4,Locations!$A$4:$J$200,6,FALSE),"") -> 485000 | F4: =IFERROR(VLOOKUP($A4,Locations!$A$4:$J$200,8,FALSE),"") -> 1.0361098 | G4: =IFERROR(D4*Inputs_Global!$B$5*F4,"") -> 1709581.1 | H4: =IFERROR(G4*Inputs_Global!$B$7,"") -> 1025748.7 | I4: =IFERROR(-E4-(Inputs_Global!$B$17 + Inputs_Global!$B$18*Inputs_Global!$B$19)-(Inputs_Global!$B$20*(Inputs_Global!$B$17 + Inputs_Global!$B$18*Inputs_Global!$B$19))-(G4*Inputs_Global!$B$8)-(Inputs_Global!$B$9 + G4*Inputs_Global!$B$10)-(Inputs_Global!$B$11)-(Inputs_Global!$B$13*D4)-(Inputs_Global!$B$14)-(Inputs_Global!$B$12)-(Inputs_Global!$B$15*D4/Inputs_Global!$B$16),"") -> -1052465.3 | J4: =IFERROR(H4+I4,"") -> -26716.61 | K4: =IFERROR(J4 - MAX(0,J4)*Inputs_Global!$B$21,"") -> -26716.61 | L4: =IFERROR((Inputs_Global!$B$15*D4) + ((G4-H4)*Inputs_Global!$B$28/12) + (E4*Inputs_Global!$B$27/12) + Inputs_Global!$B$29, "") -> 462208.11
A5: WF_SYD_SECOND | B5: =IFERROR(VLOOKUP($A5,Locations!$A$4:$J$200,2,FALSE),"") -> Sydney | C5: =IFERROR(VLOOKUP($A5,Locations!$A$4:$J$200,4,FALSE),"") -> Westfield | D5: =IFERROR(VLOOKUP($A5,Locations!$A$4:$J$200,5,FALSE),"") -> 60 | E5: =IFERROR(VLOOKUP($A5,Locations!$A$4:$J$200,6,FALSE),"") -> 350000 | F5: =IFERROR(VLOOKUP($A5,Locations!$A$4:$J$200,8,FALSE),"") -> 1.0361098 | G5: =IFERROR(D5*Inputs_Global!$B$5*F5,"") -> 1709581.1 | H5: =IFERROR(G5*Inputs_Global!$B$7,"") -> 1025748.7 | I5: =IFERROR(-E5-(Inputs_Global!$B$17 + Inputs_Global!$B$18*Inputs_Global!$B$19)-(Inputs_Global!$B$20*(Inputs_Global!$B$17 + Inputs_Global!$B$18*Inputs_Global!$B$19))-(G5*Inputs_Global!$B$8)-(Inputs_Global!$B$9 + G5*Inputs_Global!$B$10)-(Inputs_Global!$B$11)-(Inputs_Global!$B$13*D5)-(Inputs_Global!$B$14)-(Inputs_Global!$B$12)-(Inputs_Global!$B$15*D5/Inputs_Global!$B$16),"") -> -917465.29 | J5: =IFERROR(H5+I5,"") -> 108283.39 | K5: =IFERROR(J5 - MAX(0,J5)*Inputs_Global!$B$21,"") -> 81212.542 | L5: =IFERROR((Inputs_Global!$B$15*D5) + ((G5-H5)*Inputs_Global!$B$28/12) + (E5*Inputs_Global!$B$27/12) + Inputs_Global!$B$29, "") -> 428458.11
A6: WF_BONDI | B6: =IFERROR(VLOOKUP($A6,Locations!$A$4:$J$200,2,FALSE),"") -> Bondi Junction | C6: =IFERROR(VLOOKUP($A6,Locations!$A$4:$J$200,4,FALSE),"") -> Westfield | D6: =IFERROR(VLOOKUP($A6,Locations!$A$4:$J$200,5,FALSE),"") -> 60 | E6: =IFERROR(VLOOKUP($A6,Locations!$A$4:$J$200,6,FALSE),"") -> 287500 | F6: =IFERROR(VLOOKUP($A6,Locations!$A$4:$J$200,8,FALSE),"") -> 0.87455521 | G6: =IFERROR(D6*Inputs_Global!$B$5*F6,"") -> 1443016.1 | H6: =IFERROR(G6*Inputs_Global!$B$7,"") -> 865809.66 | I6: =IFERROR(-E6-(Inputs_Global!$B$17 + Inputs_Global!$B$18*Inputs_Global!$B$19)-(Inputs_Global!$B$20*(Inputs_Global!$B$17 + Inputs_Global!$B$18*Inputs_Global!$B$19))-(G6*Inputs_Global!$B$8)-(Inputs_Global!$B$9 + G6*Inputs_Global!$B$10)-(Inputs_Global!$B$11)-(Inputs_Global!$B$13*D6)-(Inputs_Global!$B$14)-(Inputs_Global!$B$12)-(Inputs_Global!$B$15*D6/Inputs_Global!$B$16),"") -> -839237.95 | J6: =IFERROR(H6+I6,"") -> 26571.712 | K6: =IFERROR(J6 - MAX(0,J6)*Inputs_Global!$B$21,"") -> 19928.784 | L6: =IFERROR((Inputs_Global!$B$15*D6) + ((G6-H6)*Inputs_Global!$B$28/12) + (E6*Inputs_Global!$B$27/12) + Inputs_Global!$B$29, "") -> 386176.61
A7: WF_PARRA | B7: =IFERROR(VLOOKUP($A7,Locations!$A$4:$J$200,2,FALSE),"") -> Parramatta | C7: =IFERROR(VLOOKUP($A7,Locations!$A$4:$J$200,4,FALSE),"") -> Westfield | D7: =IFERROR(VLOOKUP($A7,Locations!$A$4:$J$200,5,FALSE),"") -> 60 | E7: =IFERROR(VLOOKUP($A7,Locations!$A$4:$J$200,6,FALSE),"") -> 250000 | F7: =IFERROR(VLOOKUP($A7,Locations!$A$4:$J$200,8,FALSE),"") -> 0.97384697 | G7: =IFERROR(D7*Inputs_Global!$B$5*F7,"") -> 1606847.5 | H7: =IFERROR(G7*Inputs_Global!$B$7,"") -> 964108.5 | I7: =IFERROR(-E7-(Inputs_Global!$B$17 + Inputs_Global!$B$18*Inputs_Global!$B$19)-(Inputs_Global!$B$20*(Inputs_Global!$B$17 + Inputs_Global!$B$18*Inputs_Global!$B$19))-(G7*Inputs_Global!$B$8)-(Inputs_Global!$B$9 + G7*Inputs_Global!$B$10)-(Inputs_Global!$B$11)-(Inputs_Global!$B$13*D7)-(Inputs_Global!$B$14)-(Inputs_Global!$B$12)-(Inputs_Global!$B$15*D7/Inputs_Global!$B$16),"") -> -811404 | J7: =IFERROR(H7+I7,"") -> 152704.5 | K7: =IFERROR(J7 - MAX(0,J7)*Inputs_Global!$B$21,"") -> 114528.37 | L7: =IFERROR((Inputs_Global!$B$15*D7) + ((G7-H7)*Inputs_Global!$B$28/12) + (E7*Inputs_Global!$B$27/12) + Inputs_Global!$B$29, "") -> 393184.75
A8: WF_CHATSWOOD | B8: =IFERROR(VLOOKUP($A8,Locations!$A$4:$J$200,2,FALSE),"") -> Chatswood | C8: =IFERROR(VLOOKUP($A8,Locations!$A$4:$J$200,4,FALSE),"") -> Westfield | D8: =IFERROR(VLOOKUP($A8,Locations!$A$4:$J$200,5,FALSE),"") -> 60 | E8: =IFERROR(VLOOKUP($A8,Locations!$A$4:$J$200,6,FALSE),"") -> 260000 | F8: =IFERROR(VLOOKUP($A8,Locations!$A$4:$J$200,8,FALSE),"") -> 0.76115822 | G8: =IFERROR(D8*Inputs_Global!$B$5*F8,"") -> 1255911.1 | H8: =IFERROR(G8*Inputs_Global!$B$7,"") -> 753546.64 | I8: =IFERROR(-E8-(Inputs_Global!$B$17 + Inputs_Global!$B$18*Inputs_Global!$B$19)-(Inputs_Global!$B$20*(Inputs_Global!$B$17 + Inputs_Global!$B$18*Inputs_Global!$B$19))-(G8*Inputs_Global!$B$8)-(Inputs_Global!$B$9 + G8*Inputs_Global!$B$10)-(Inputs_Global!$B$11)-(Inputs_Global!$B$13*D8)-(Inputs_Global!$B$14)-(Inputs_Global!$B$12)-(Inputs_Global!$B$15*D8/Inputs_Global!$B$16),"") -> -800698.75 | J8: =IFERROR(H8+I8,"") -> -47152.114 | K8: =IFERROR(J8 - MAX(0,J8)*Inputs_Global!$B$21,"") -> -47152.114 | L8: =IFERROR((Inputs_Global!$B$15*D8) + ((G8-H8)*Inputs_Global!$B$28/12) + (E8*Inputs_Global!$B$27/12) + Inputs_Global!$B$29, "") -> 360591.11
A9: WF_MIRANDA | B9: =IFERROR(VLOOKUP($A9,Locations!$A$4:$J$200,2,FALSE),"") -> Miranda | C9: =IFERROR(VLOOKUP($A9,Locations!$A$4:$J$200,4,FALSE),"") -> Westfield | D9: =IFERROR(VLOOKUP($A9,Locations!$A$4:$J$200,5,FALSE),"") -> 60 | E9: =IFERROR(VLOOKUP($A9,Locations!$A$4:$J$200,6,FALSE),"") -> 210000 | F9: =IFERROR(VLOOKUP($A9,Locations!$A$4:$J$200,8,FALSE),"") -> 0.68610411 | G9: =IFERROR(D9*Inputs_Global!$B$5*F9,"") -> 1132071.8 | H9: =IFERROR(G9*Inputs_Global!$B$7,"") -> 679243.07 | I9: =IFERROR(-E9-(Inputs_Global!$B$17 + Inputs_Global!$B$18*Inputs_Global!$B$19)-(Inputs_Global!$B$20*(Inputs_Global!$B$17 + Inputs_Global!$B$18*Inputs_Global!$B$19))-(G9*Inputs_Global!$B$8)-(Inputs_Global!$B$9 + G9*Inputs_Global!$B$10)-(Inputs_Global!$B$11)-(Inputs_Global!$B$13*D9)-(Inputs_Global!$B$14)-(Inputs_Global!$B$12)-(Inputs_Global!$B$15*D9/Inputs_Global!$B$16),"") -> -743392.23 | J9: =IFERROR(H9+I9,"") -> -64149.169 | K9: =IFERROR(J9 - MAX(0,J9)*Inputs_Global!$B$21,"") -> -64149.169 | L9: =IFERROR((Inputs_Global!$B$15*D9) + ((G9-H9)*Inputs_Global!$B$28/12) + (E9*Inputs_Global!$B$27/12) + Inputs_Global!$B$29, "") -> 335707.18
A10: WF_WARRINGAH | B10: =IFERROR(VLOOKUP($A10,Locations!$A$4:$J$200,2,FALSE),"") -> Warringah Mall | C10: =IFERROR(VLOOKUP($A10,Locations!$A$4:$J$200,4,FALSE),"") -> Westfield | D10: =IFERROR(VLOOKUP($A10,Locations!$A$4:$J$200,5,FALSE),"") -> 60 | E10: =IFERROR(VLOOKUP($A10,Locations!$A$4:$J$200,6,FALSE),"") -> 250000 | F10: =IFERROR(VLOOKUP($A10,Locations!$A$4:$J$200,8,FALSE),"") -> 0.67380065 | G10: =IFERROR(D10*Inputs_Global!$B$5*F10,"") -> 1111771.1 | H10: =IFERROR(G10*Inputs_Global!$B$7,"") -> 667062.65 | I10: =IFERROR(-E10-(Inputs_Global!$B$17 + Inputs_Global!$B$18*Inputs_Global!$B$19)-(Inputs_Global!$B$20*(Inputs_Global!$B$17 + Inputs_Global!$B$18*Inputs_Global!$B$19))-(G10*Inputs_Global!$B$8)-(Inputs_Global!$B$9 + G10*Inputs_Global!$B$10)-(Inputs_Global!$B$11)-(Inputs_Global!$B$13*D10)-(Inputs_Global!$B$14)-(Inputs_Global!$B$12)-(Inputs_Global!$B$15*D10/Inputs_Global!$B$16),"") -> -782194.49 | J10: =IFERROR(H10+I10,"") -> -115131.85 | K10: =IFERROR(J10 - MAX(0,J10)*Inputs_Global!$B$21,"") -> -115131.85 | L10: =IFERROR((Inputs_Global!$B$15*D10) + ((G10-H10)*Inputs_Global!$B$28/12) + (E10*Inputs_Global!$B$27/12) + Inputs_Global!$B$29, "") -> 343677.11
A11: ST_CBD_CASTL | B11: =IFERROR(VLOOKUP($A11,Locations!$A$4:$J$200,2,FALSE),"") -> Sydney CBD | C11: =IFERROR(VLOOKUP($A11,Locations!$A$4:$J$200,4,FALSE),"") -> Street High-End | D11: =IFERROR(VLOOKUP($A11,Locations!$A$4:$J$200,5,FALSE),"") -> 60 | E11: =IFERROR(VLOOKUP($A11,Locations!$A$4:$J$200,6,FALSE),"") -> 450000 | F11: =IFERROR(VLOOKUP($A11,Locations!$A$4:$J$200,8,FALSE),"") -> 1.0074627 | G11: =IFERROR(D11*Inputs_Global!$B$5*F11,"") -> 1662313.4 | H11: =IFERROR(G11*Inputs_Global!$B$7,"") -> 997388.06 | I11: =IFERROR(-E11-(Inputs_Global!$B$17 + Inputs_Global!$B$18*Inputs_Global!$B$19)-(Inputs_Global!$B$20*(Inputs_Global!$B$17 + Inputs_Global!$B$18*Inputs_Global!$B$19))-(G11*Inputs_Global!$B$8)-(Inputs_Global!$B$9 + G11*Inputs_Global!$B$10)-(Inputs_Global!$B$11)-(Inputs_Global!$B$13*D11)-(Inputs_Global!$B$14)-(Inputs_Global!$B$12)-(Inputs_Global!$B$15*D11/Inputs_Global!$B$16),"") -> -1014676.5 | J11: =IFERROR(H11+I11,"") -> -17288.433 | K11: =IFERROR(J11 - MAX(0,J11)*Inputs_Global!$B$21,"") -> -17288.433 | L11: =IFERROR((Inputs_Global!$B$15*D11) + ((G11-H11)*Inputs_Global!$B$28/12) + (E11*Inputs_Global!$B$27/12) + Inputs_Global!$B$29, "") -> 448731.34
A12: ST_CBD_PITT | B12: =IFERROR(VLOOKUP($A12,Locations!$A$4:$J$200,2,FALSE),"") -> Sydney CBD | C12: =IFERROR(VLOOKUP($A12,Locations!$A$4:$J$200,4,FALSE),"") -> Street Prime Strip | D12: =IFERROR(VLOOKUP($A12,Locations!$A$4:$J$200,5,FALSE),"") -> 60 | E12: =IFERROR(VLOOKUP($A12,Locations!$A$4:$J$200,6,FALSE),"") -> 780000 | F12: =IFERROR(VLOOKUP($A12,Locations!$A$4:$J$200,8,FALSE),"") -> 1.0074627 | G12: =IFERROR(D12*Inputs_Global!$B$5*F12,"") -> 1662313.4 | H12: =IFERROR(G12*Inputs_Global!$B$7,"") -> 997388.06 | I12: =IFERROR(-E12-(Inputs_Global!$B$17 + Inputs_Global!$B$18*Inputs_Global!$B$19)-(Inputs_Global!$B$20*(Inputs_Global!$B$17 + Inputs_Global!$B$18*Inputs_Global!$B$19))-(G12*Inputs_Global!$B$8)-(Inputs_Global!$B$9 + G12*Inputs_Global!$B$10)-(Inputs_Global!$B$11)-(Inputs_Global!$B$13*D12)-(Inputs_Global!$B$14)-(Inputs_Global!$B$12)-(Inputs_Global!$B$15*D12/Inputs_Global!$B$16),"") -> -1344676.5 | J12: =IFERROR(H12+I12,"") -> -347288.43 | K12: =IFERROR(J12 - MAX(0,J12)*Inputs_Global!$B$21,"") -> -347288.43 | L12: =IFERROR((Inputs_Global!$B$15*D12) + ((G12-H12)*Inputs_Global!$B$28/12) + (E12*Inputs_Global!$B$27/12) + Inputs_Global!$B$29, "") -> 531231.34
A13: ST_CHIN_HAY | B13: =IFERROR(VLOOKUP($A13,Locations!$A$4:$J$200,2,FALSE),"") -> Chinatown | C13: =IFERROR(VLOOKUP($A13,Locations!$A$4:$J$200,4,FALSE),"") -> Street Ethnic Cluster | D13: =IFERROR(VLOOKUP($A13,Locations!$A$4:$J$200,5,FALSE),"") -> 60 | E13: =IFERROR(VLOOKUP($A13,Locations!$A$4:$J$200,6,FALSE),"") -> 180000 | F13: =IFERROR(VLOOKUP($A13,Locations!$A$4:$J$200,8,FALSE),"") -> 0.96485315 | G13: =IFERROR(D13*Inputs_Global!$B$5*F13,"") -> 1592007.7 | H13: =IFERROR(G13*Inputs_Global!$B$7,"") -> 955204.62 | I13: =IFERROR(-E13-(Inputs_Global!$B$17 + Inputs_Global!$B$18*Inputs_Global!$B$19)-(Inputs_Global!$B$20*(Inputs_Global!$B$17 + Inputs_Global!$B$18*Inputs_Global!$B$19))-(G13*Inputs_Global!$B$8)-(Inputs_Global!$B$9 + G13*Inputs_Global!$B$10)-(Inputs_Global!$B$11)-(Inputs_Global!$B$13*D13)-(Inputs_Global!$B$14)-(Inputs_Global!$B$12)-(Inputs_Global!$B$15*D13/Inputs_Global!$B$16),"") -> -740528.45 | J13: =IFERROR(H13+I13,"") -> 214676.17 | K13: =IFERROR(J13 - MAX(0,J13)*Inputs_Global!$B$21,"") -> 161007.13 | L13: =IFERROR((Inputs_Global!$B$15*D13) + ((G13-H13)*Inputs_Global!$B$28/12) + (E13*Inputs_Global!$B$27/12) + Inputs_Global!$B$29, "") -> 374200.77
A14: ST_CHAT_VIC | B14: =IFERROR(VLOOKUP($A14,Locations!$A$4:$J$200,2,FALSE),"") -> Chatswood | C14: =IFERROR(VLOOKUP($A14,Locations!$A$4:$J$200,4,FALSE),"") -> Street High Street | D14: =IFERROR(VLOOKUP($A14,Locations!$A$4:$J$200,5,FALSE),"") -> 60 | E14: =IFERROR(VLOOKUP($A14,Locations!$A$4:$J$200,6,FALSE),"") -> 270000 | F14: =IFERROR(VLOOKUP($A14,Locations!$A$4:$J$200,8,FALSE),"") -> 0.76115822 | G14: =IFERROR(D14*Inputs_Global!$B$5*F14,"") -> 1255911.1 | H14: =IFERROR(G14*Inputs_Global!$B$7,"") -> 753546.64 | I14: =IFERROR(-E14-(Inputs_Global!$B$17 + Inputs_Global!$B$18*Inputs_Global!$B$19)-(Inputs_Global!$B$20*(Inputs_Global!$B$17 + Inputs_Global!$B$18*Inputs_Global!$B$19))-(G14*Inputs_Global!$B$8)-(Inputs_Global!$B$9 + G14*Inputs_Global!$B$10)-(Inputs_Global!$B$11)-(Inputs_Global!$B$13*D14)-(Inputs_Global!$B$14)-(Inputs_Global!$B$12)-(Inputs_Global!$B$15*D14/Inputs_Global!$B$16),"") -> -810698.75 | J14: =IFERROR(H14+I14,"") -> -57152.114 | K14: =IFERROR(J14 - MAX(0,J14)*Inputs_Global!$B$21,"") -> -57152.114 | L14: =IFERROR((Inputs_Global!$B$15*D14) + ((G14-H14)*Inputs_Global!$B$28/12) + (E14*Inputs_Global!$B$27/12) + Inputs_Global!$B$29, "") -> 363091.11

Sheet Mappings
A1: Mappings (helper): standardises names → Location_ID (used for consistent lookups)
A2: If a source dataset uses a different wording for the same place, add it here so all formulas still work.
A3: Anchor Location | B3: Mapped_Location_ID | C3: Mapping note
A4: Castlereagh St luxury cluster | B4: ST_CBD_CASTL | C4: Direct match (candidate cluster)
A5: King St luxury cluster | B5: ST_CBD_CASTL | C5: Proxy: CBD luxury cluster (validate)
A6: Pitt St Mall jewellery cluster | B6: ST_CBD_PITT | C6: Direct match (candidate cluster)
A7: Queen Victoria Building (QVB) | B7: ST_CBD_PITT | C7: Proxy: CBD prime retail (validate)
A8: Hay St Chinese jewellery strip | B8: ST_CHIN_HAY | C8: Direct match (candidate cluster)
A9: Sussex St Haymarket jewellery | B9: ST_CHIN_HAY | C9: Proxy: Chinatown/Haymarket (validate)
A10: Westfield Bondi Junction | B10: WF_BONDI | C10: Direct match (candidate centre)
A11: Westfield Chatswood | B11: WF_CHATSWOOD | C11: Direct match (candidate centre)

Sheet Metrics_Library
A1: Metrics to collect (P&L drivers + spatial indicators)
A3: Metric | B3: Category | C3: Short definition | D3: Used in current P&L? | E3: Data availability | F3: Geography level | G3: Source URL(s) | H3: Why it matters / how to use
A4: Store size (sqm) | B4: Store | C4: Net lettable area for the store | D4: Y | E4: Internal / lease | F4: Store | G4: (lease plan / landlord) | H4: Key driver of revenue (sales density) and fitout capex.
A5: Base rent (AUD/year) | B5: Rent | C5: Fixed base rent under lease (excl. turnover) | D5: Y | E5: Internal / landlord | F5: Store | G5: (lease schedule / landlord) | H5: Largest fixed cost; also drives deposit and feasibility.
A6: Fitout capex (AUD/sqm) | B6: Capex | C6: Initial store fitout cost per sqm | D6: Y | E6: Benchmark + quotes | F6: Store | G6: https://www.totalfitouts.com.au/blog/2025-pricing-per-square-meter-m%C2%B2-for-fitouts-in-australia/ | H6: Drives initial investment and depreciation.
A7: Sales per sqm (AUD/sqm/year) | B7: Revenue | C7: Annual sales density benchmark | D7: Scentre Group 2024 Property Compendium: Specialty Sales (MAT) $/sqm for specialty stores <400sqm. Used as a defensible base sales density until CTS internal store benchmarks are available. | E7: https://assets.ctfassets.net/0vreywxqlgab/2jCDgyNRHOqTByrcni3uKv/47f440c291228ef086d42355f46d237f/2024_Property_Compendium.xlsx | F7: Centre/Store proxy | G7: https://assets.ctfassets.net/0vreywxqlgab/2jCDgyNRHOqTByrcni3uKv/47f440c291228ef086d42355f46d237f/2024_Property_Compendium.xlsx | H7: Anchors Year-1 revenue baseline; location differences handled via Sales_Index.
A8: Sales_Index (income+footfall) | B8: Revenue proxy | C8: Composite index from income and footfall proxies | D8: Sales Index blends two normalised proxies: Income_Index (median weekly household income vs baseline) and Footfall_Index (annual visits vs baseline). Sales_Index = IncomeWeight*Income_Index + FootfallWeight*Footfall_Index. We use this because direct store revenue forecasts by precinct are not available; the index keeps the model location‑sensitive using observable proxies. | E8: (see Inputs_Global for weights + sources) | F8: SA2 + centre/station | G8: ABS QuickStats + Scentre / TfNSW / City of Sydney | H8: Makes revenue district-sensitive when store-level sales data is unavailable.
A9: Gross margin (%) | B9: Margin | C9: 1-COGS% of sales | D9: Jewellery retailer gross margin reference point; Michael Hill reported ~60.4% gross margin in FY2024. Used as starting point until CTS product mix / margin targets are provided. | E9: https://announcements.asx.com.au/asxpdf/20240829/pdf/0668rfd20kzj4j.pdf | F9: Store (proxy) | G9: https://announcements.asx.com.au/asxpdf/20240830/pdf/067c0yy1h0157n.pdf | https://announcements.asx.com.au/asxpdf/20240827/pdf/0672gm873byl16.pdf | H9: Major driver of profitability; replace with CTS product mix targets.
A10: Merchant fee rate (%) | B10: Payments | C10: Average merchant service fees as % of sales | D10: Y | E10: Yes | F10: National | G10: https://www.rba.gov.au/statistics/frequency/retail-payments/2025/retail-payments-0225.html | H10: Scales with revenue; can be validated with merchant acquiring quotes.
A11: Award wage rates + penalties | B11: Labour | C11: Minimum wage rates and penalty rates | D11: Y | E11: Yes | F11: National | G11: https://portal.fairwork.gov.au/ArticleDocuments/872/general-retail-industry-award-ma000004-pay-guide.pdf.aspx | H11: Supports staffing cost modelling; later used for roster-level detail.
A12: Superannuation guarantee rate | B12: Labour | C12: Employer super rate on ordinary time earnings | D12: Y | E12: Yes | F12: National | G12: https://www.ato.gov.au/tax-rates-and-codes/key-superannuation-rates-and-thresholds/super-guarantee | H12: Mandatory add-on to wages; used in OPEX.
A13: Company tax rate | B13: Tax | C13: Corporate income tax rate | D13: Y | E13: Yes | F13: National | G13: https://www.ato.gov.au/tax-rates-and-codes/company-tax-rate-changes | H13: Used for after-tax profit and NPV cash flows.
A14: CPI inflation (annual) | B14: Macro | C14: Annual CPI (used as discount & escalation rate) | D14: Y | E14: Yes | F14: National | G14: https://www.abs.gov.au/statistics/economy/price-indexes-and-inflation/consumer-price-index-australia/latest-release | H14: Discount rate proxy + cost escalation for rent/OPEX in NPV.
... A18: Competition count (manual) | B18: Competition | C18: Count of comparable jewellery competitors near site | D18: N (supports) | E18: Manual / Google Maps | F18: Local | G18: (manual collection) | H18: Supports qualitative scoring and potential Sales_Index adjustments.

Sheet Input_Data_Clusters
A1: Input data – Clusters (from Sydney_Jewellery_Locations_Tableau_v2.xlsx)
A3: Area | B3: Location | C3: Latitude | D3: Longitude
A4: Sydney CBD | B4: Castlereagh St luxury cluster | C4: -33.86863 | D4: 151.20703
A5: Sydney CBD | B5: King St luxury cluster | C5: -33.86794 | D5: 151.20866
A6: Sydney CBD | B6: Pitt St Mall jewellery cluster | C6: -33.87044 | D6: 151.20835
A7: Sydney CBD | B7: Strand Arcade (412–414 George St) | C7: -33.86989 | D7: 151.20654
A8: Sydney CBD | B8: Queen Victoria Building (QVB) | C8: -33.87135 | D8: 151.20658
A9: Chinatown | B9: Dixon St Chinatown core | C9: -33.87668 | D9: 151.20462
A10: Chinatown | B10: Hay St Chinese jewellery strip | C10: -33.87742 | D10: 151.20391
A11: Chinatown | B11: Sussex St Haymarket jewellery | C11: -33.87801 | D11: 151.20264
A12: Chatswood | B12: Westfield Chatswood | C12: -33.79658 | D12: 151.18203
A13: Chatswood | B13: Mandarin Centre Chatswood | C13: -33.79694 | D13: 151.18076
A14: Chatswood | B14: Victoria Ave retail strip | C14: -33.79611 | D14: 151.18141
A15: Bondi Junction | B15: Westfield Bondi Junction | C15: -33.8927 | D15: 151.24802

Sheet Input_Data_Brands
A1: Input data – Brands / competitor stores (from Sydney_Jewellery_Locations_Tableau_v2.xlsx)
A3: Brand | B3: Area | C3: Anchor Location | D3: Rule Applied | E3: Latitude | F3: Longitude
A4: Cartier | B4: Sydney CBD | C4: Castlereagh St luxury cluster | D4: Street (Option A) | E4: -33.86863 | F4: 151.20703
A5: Tiffany & Co. | B5: Sydney CBD | C5: Castlereagh St luxury cluster | D5: Street (Option A) | E5: -33.86863 | F5: 151.20703
A6: Bulgari | B6: Sydney CBD | C6: Castlereagh St luxury cluster | D6: Street (Option A) | E6: -33.86863 | F6: 151.20703
A7: Van Cleef & Arpels | B7: Sydney CBD | C7: Castlereagh St luxury cluster | D7: Street (Option A) | E7: -33.86863 | F7: 151.20703
A8: Rolex Boutique | B8: Sydney CBD | C8: King St luxury cluster | D8: Street (Option A) | E8: -33.86794 | F8: 151.20866
A9: Patek Philippe | B9: Sydney CBD | C9: King St luxury cluster | D9: Street (Option A) | E9: -33.86794 | F9: 151.20866
A10: Chanel Fine Jewellery | B10: Sydney CBD | C10: Castlereagh St luxury cluster | D10: Street (Option A) | E10: -33.86863 | F10: 151.20703
A11: Dior Joaillerie | B11: Sydney CBD | C11: Castlereagh St luxury cluster | D11: Street (Option A) | E11: -33.86863 | F11: 151.20703
A12: Michael Hill | B12: Sydney CBD | C12: Pitt St Mall jewellery cluster | D12: Street (Option A) | E12: -33.87044 | F12: 151.20835
A13: Angus & Coote | B13: Sydney CBD | C13: Pitt St Mall jewellery cluster | D13: Street (Option A) | E13: -33.87044 | F13: 151.20835
A14: Prouds | B14: Sydney CBD | C14: Pitt St Mall jewellery cluster | D14: Street (Option A) | E14: -33.87044 | F14: 151.20835
A15: Wallace Bishop | B15: Sydney CBD | C15: Queen Victoria Building (QVB) | D15: Complex (Option A/B) | E15: -33.87135 | F15: 151.20658
... A34: Swarovski | B34: Bondi Junction | C34: Westfield Bondi Junction | D34: Mall (Option B) | E34: -33.8927 | F34: 151.24802

Sheet Input_Data_WestfieldRent
A1: Input data – Westfield rent benchmarks (from Sydney_Jewellery_Locations_Tableau_v2.xlsx)
B4: Westfield Centre | C4: Location Type | D4: Indicative Rent (AUD / sqm / year) | E4: Typical Store Size (sqm) | F4: Estimated Annual Base Rent (AUD) | G4: Notes (Jewellery-relevant)
B5: Westfield Sydney | C5: CBD Prime Internal Mall | D5: 8,000 – 12,000 | E5: 40–70 | F5: 320,000 – 650,000 | G5: Highest footfall, highest risk
B6: Westfield Sydney | C6: CBD Secondary Mall | D6: 5,000 – 7,500 | E6: 40–70 | F6: 200,000 – 500,000 | G6: Lower visibility but still premium
B7: Westfield Bondi Junction | C7: Urban Flagship | D7: 3,500 – 5,000 | E7: 50–80 | F7: 175,000 – 400,000 | G7: Tourist + affluent locals
B8: Westfield Parramatta | C8: Regional Prime | D8: 2,500 – 3,800 | E8: 60–100 | F8: 150,000 – 350,000 | G8: Strong conversion, lower rent pressure
B9: Westfield Chatswood | C9: Regional Prime | D9: 2,800 – 4,200 | E9: 50–90 | F9: 140,000 – 380,000 | G9: High Asian consumer density
B10: Westfield Miranda | C10: Suburban | D10: 2,000 – 3,000 | E10: 60–100 | F10: 120,000 – 300,000 | G10: Family-driven spending
B11: Westfield Warringah Mall | C11: Suburban Premium | D11: 2,500 – 3,500 | E11: 60–100 | F11: 150,000 – 350,000 | G11: Lifestyle-focused centre
B14: Typical Jewwellery shop size | D14: ~ 60 sqm (40-70)

Sheet Dashboard_Data
A1: Location_ID | B1: Area | C1: Type | D1: Store_Size_sqm | E1: SA2_CODE21 | F1: SA2_NAME21 | G1: Centroid_Lat | H1: Centroid_Lon | I1: SA2_Mapping_Method | J1: Last_Updated | K1: Sales_Index | L1: Revenue_pa | M1: COGS_pa | N1: Gross_Profit_pa | O1: Rent_pa | P1: Other_OPEX_pa | Q1: Total_OPEX_pa | R1: EBIT_pa | S1: Net_Income_pa | T1: Initial_Investment_AUD | U1: NPV_5y_AUD | V1: Gross_Margin_% | W1: EBIT_Margin_% | X1: Net_Margin_%
A2: WF_SYD_PRIME | B2: Sydney | C2: Westfield | D2: 60 | E2: 117031645 | F2: Sydney (South) - Haymarket | G2: -33.877065 | H2: 151.20247 | I2: Area-to-SA2 (manual mapping; edit if needed) | J2: 2026-02-14 | K2: 1.0361098 | L2: 1709581.1 | M2: 683832.45 | N2: 1025748.7 | O2: 485000 | P2: 567465.29 | Q2: 1052465.3 | R2: -26716.61 | S2: -26716.61 | T2: 462208.11 | U2: -593910.99 | V2: 0.6 | W2: -0.015627577 | X2: -0.015627577
A3: WF_SYD_SECOND | B3: Sydney | C3: Westfield | D3: 60 | E3: 117031645 | F3: Sydney (South) - Haymarket | G3: -33.877065 | H3: 151.20247 | I3: Area-to-SA2 (manual mapping; edit if needed) | J3: 2026-02-14 | K3: 1.0361098 | L3: 1709581.1 | M3: 683832.45 | N3: 1025748.7 | O3: 350000 | P3: 567465.29 | Q3: 917465.29 | R3: 108283.39 | S3: 81212.542 | T3: 428458.11 | U3: -28110.701 | V3: 0.6 | W3: 0.063339135 | X3: 0.047504351
A4: WF_BONDI | B4: Bondi Junction | C4: Westfield | D4: 60 | E4: 118011341 | F4: Bondi Junction - Waverly | G4: -33.896088 | H4: 151.25305 | I4: Area-to-SA2 (manual mapping; edit if needed) | J4: 2026-02-14 | K4: 0.87455521 | L4: 1443016.1 | M4: 577206.44 | N4: 865809.66 | O4: 287500 | P4: 551737.95 | Q4: 839237.95 | R4: 26571.712 | S4: 19928.784 | T4: 386176.61 | U4: -287935.17 | V4: 0.6 | W4: 0.018414009 | X4: 0.013810507
A5: WF_PARRA | B5: Parramatta | C5: Westfield | D5: 60 | E5: 125041718 | F5: Parramatta - South | G5: -33.82319 | H5: 151.00005 | I5: Area-to-SA2 (manual mapping; edit if needed) | J5: 2026-02-14 | K5: 0.97384697 | L5: 1606847.5 | M5: 642739 | N5: 964108.5 | O5: 250000 | P5: 561404 | Q5: 811404 | R5: 152704.5 | S5: 114528.37 | T5: 393184.75 | U5: 171397.22 | V5: 0.6 | W5: 0.095033596 | X5: 0.071275197
A6: WF_CHATSWOOD | B6: Chatswood | C6: Westfield | D6: 60 | E6: 121011684 | F6: Chatswood - East | G6: -33.793653 | H6: 151.18755 | I6: Area-to-SA2 (manual mapping; edit if needed) | J6: 2026-02-14 | K6: 0.76115822 | L6: 1255911.1 | M6: 502364.43 | N6: 753546.64 | O6: 260000 | P6: 540698.75 | Q6: 800698.75 | R6: -47152.114 | S6: -47152.114 | T6: 360591.11 | U6: -593033.36 | V6: 0.6 | W6: -0.03754415 | X6: -0.03754415
A7: WF_MIRANDA | B7: Miranda | C7: Westfield | D7: 60 | E7: 128011530 | F7: Miranda - Yowie Bay | G7: -34.04751 | H7: 151.10452 | I7: Area-to-SA2 (manual mapping; edit if needed) | J7: 2026-02-14 | K7: 0.68610411 | L7: 1132071.8 | M7: 452828.71 | N7: 679243.07 | O7: 210000 | P7: 533392.23 | Q7: 743392.23 | R7: -64149.169 | S7: -64149.169 | T7: 335707.18 | U7: -651938.55 | V7: 0.6 | W7: -0.056665285 | X7: -0.056665285
A8: WF_WARRINGAH | B8: Warringah Mall | C8: Westfield | D8: 60 | E8: 122031429 | F8: Freshwater - Brookvale | G8: -33.772912 | H8: 151.28262 | I8: Area-to-SA2 (manual mapping; edit if needed) | J8: 2026-02-14 | K8: 0.67380065 | L8: 1111771.1 | M8: 444708.43 | N8: 667062.65 | O8: 250000 | P8: 532194.49 | Q8: 782194.49 | R8: -115131.85 | S8: -115131.85 | T8: 343677.11 | U8: -911233.99 | V8: 0.6 | W8: -0.10355715 | X8: -0.10355715
A9: ST_CBD_CASTL | B9: Sydney CBD | C9: Street High-End | D9: 60 | E9: 117031645 | F9: Sydney (South) - Haymarket | G9: -33.877065 | H9: 151.20247 | I9: Area-to-SA2 (manual mapping; edit if needed) | J9: 2026-02-14 | K9: 1.0074627 | L9: 1662313.4 | M9: 664925.37 | N9: 997388.06 | O9: 450000 | P9: 564676.49 | Q9: 1014676.5 | R9: -17288.433 | S9: -17288.433 | T9: 448731.34 | U9: -533956.84 | V9: 0.6 | W9: -0.010400224 | X9: -0.010400224
A10: ST_CBD_PITT | B10: Sydney CBD | C10: Street Prime Strip | D10: 60 | E10: 117031645 | F10: Sydney (South) - Haymarket | G10: -33.877065 | H10: 151.20247 | I10: Area-to-SA2 (manual mapping; edit if needed) | J10: 2026-02-14 | K10: 1.0074627 | L10: 1662313.4 | M10: 664925.37 | N10: 997388.06 | O10: 780000 | P10: 564676.49 | Q10: 1344676.5 | R10: -347288.43 | S10: -347288.43 | T10: 531231.34 | U10: -2243233.2 | V10: 0.6 | W10: -0.20891874 | X10: -0.20891874
A11: ST_CHIN_HAY | B11: Chinatown | C11: Street Ethnic Cluster | D11: 60 | E11: 117031645 | F11: Sydney (South) - Haymarket | G11: -33.877065 | H11: 151.20247 | I11: Area-to-SA2 (manual mapping; edit if needed) | J11: 2026-02-14 | K11: 0.96485315 | L11: 1592007.7 | M11: 636803.08 | N11: 955204.62 | O11: 180000 | P11: 560528.45 | Q11: 740528.45 | R11: 214676.17 | S11: 161007.13 | T11: 374200.77 | U11: 419504.05 | V11: 0.6 | W11: 0.13484619 | X11: 0.10113464
A12: ST_CHAT_VIC | B12: Chatswood | C12: Street High Street | D12: 60 | E12: 121011684 | F12: Chatswood - East | G12: -33.793653 | H12: 151.18755 | I12: Area-to-SA2 (manual mapping; edit if needed) | J12: 2026-02-14 | K12: 0.76115822 | L12: 1255911.1 | M12: 502364.43 | N12: 753546.64 | O12: 270000 | P12: 540698.75 | Q12: 810698.75 | R12: -57152.114 | S12: -57152.114 | T12: 363091.11 | U12: -644829.62 | V12: 0.6 | W12: -0.045506498 | X12: -0.045506498
